<?xml version="1.0"?>
<?xml version="1.0"?><robot name="pepe">
	<link name="0">
		<visual>
			<geometry>
				<cylinder length="0.5048117955532325" radius="2.7320874403158335e-05"/>
			</geometry>
		</visual>
		<collision>
			<geometry>
				<cylinder length="0.5048117955532325" radius="2.7320874403158335e-05"/>
			</geometry>
		</collision>
		<inertial>
			<mass value="1.183773344290807e-09"/>
			<inertia ixx="0.03" iyy="0.03" izz="0.03" ixy="0" ixz="0" iyx="0"/>
		</inertial>
	</link>
	<link name="11">
		<visual>
			<geometry>
				<cylinder length="0.32259122144523655" radius="0.09583893574017033"/>
			</geometry>
		</visual>
		<collision>
			<geometry>
				<cylinder length="0.32259122144523655" radius="0.09583893574017033"/>
			</geometry>
		</collision>
		<inertial>
			<mass value="0.009308643162155331"/>
			<inertia ixx="0.03" iyy="0.03" izz="0.03" ixy="0" ixz="0" iyx="0"/>
		</inertial>
	</link>
	<link name="22">
		<visual>
			<geometry>
				<cylinder length="0.029411056662383417" radius="0.8685385889465416"/>
			</geometry>
		</visual>
		<collision>
			<geometry>
				<cylinder length="0.029411056662383417" radius="0.8685385889465416"/>
			</geometry>
		</collision>
		<inertial>
			<mass value="0.06970095653722083"/>
			<inertia ixx="0.03" iyy="0.03" izz="0.03" ixy="0" ixz="0" iyx="0"/>
		</inertial>
	</link>
	<link name="23">
		<visual>
			<geometry>
				<cylinder length="0.029411056662383417" radius="0.8685385889465416"/>
			</geometry>
		</visual>
		<collision>
			<geometry>
				<cylinder length="0.029411056662383417" radius="0.8685385889465416"/>
			</geometry>
		</collision>
		<inertial>
			<mass value="0.06970095653722083"/>
			<inertia ixx="0.03" iyy="0.03" izz="0.03" ixy="0" ixz="0" iyx="0"/>
		</inertial>
	</link>
	<link name="24">
		<visual>
			<geometry>
				<cylinder length="0.029411056662383417" radius="0.8685385889465416"/>
			</geometry>
		</visual>
		<collision>
			<geometry>
				<cylinder length="0.029411056662383417" radius="0.8685385889465416"/>
			</geometry>
		</collision>
		<inertial>
			<mass value="0.06970095653722083"/>
			<inertia ixx="0.03" iyy="0.03" izz="0.03" ixy="0" ixz="0" iyx="0"/>
		</inertial>
	</link>
	<link name="25">
		<visual>
			<geometry>
				<cylinder length="0.029411056662383417" radius="0.8685385889465416"/>
			</geometry>
		</visual>
		<collision>
			<geometry>
				<cylinder length="0.029411056662383417" radius="0.8685385889465416"/>
			</geometry>
		</collision>
		<inertial>
			<mass value="0.06970095653722083"/>
			<inertia ixx="0.03" iyy="0.03" izz="0.03" ixy="0" ixz="0" iyx="0"/>
		</inertial>
	</link>
	<link name="36">
		<visual>
			<geometry>
				<cylinder length="0.7480551579704343" radius="0.20925111178229627"/>
			</geometry>
		</visual>
		<collision>
			<geometry>
				<cylinder length="0.7480551579704343" radius="0.20925111178229627"/>
			</geometry>
		</collision>
		<inertial>
			<mass value="0.10290086909378822"/>
			<inertia ixx="0.03" iyy="0.03" izz="0.03" ixy="0" ixz="0" iyx="0"/>
		</inertial>
	</link>
	<link name="37">
		<visual>
			<geometry>
				<cylinder length="0.7480551579704343" radius="0.20925111178229627"/>
			</geometry>
		</visual>
		<collision>
			<geometry>
				<cylinder length="0.7480551579704343" radius="0.20925111178229627"/>
			</geometry>
		</collision>
		<inertial>
			<mass value="0.10290086909378822"/>
			<inertia ixx="0.03" iyy="0.03" izz="0.03" ixy="0" ixz="0" iyx="0"/>
		</inertial>
	</link>
	<link name="38">
		<visual>
			<geometry>
				<cylinder length="0.7480551579704343" radius="0.20925111178229627"/>
			</geometry>
		</visual>
		<collision>
			<geometry>
				<cylinder length="0.7480551579704343" radius="0.20925111178229627"/>
			</geometry>
		</collision>
		<inertial>
			<mass value="0.10290086909378822"/>
			<inertia ixx="0.03" iyy="0.03" izz="0.03" ixy="0" ixz="0" iyx="0"/>
		</inertial>
	</link>
	<joint name="11_to_0" type="revolute">
		<parent link="0"/>
		<child link="11"/>
		<axis xyz="0 0 1"/>
		<limit effort="1" upper="-3.1415" lower="3.1415" velocity="1"/>
		<origin rpy="10.390585820144286 3.8445559407021572 2.293375948059143" xyz="0.6120451870075865 0.03544172426874903 0.638708524727703"/>
	</joint>
	<joint name="22_to_11" type="revolute">
		<parent link="11"/>
		<child link="22"/>
		<axis xyz="0 1 0"/>
		<limit effort="1" upper="-3.1415" lower="3.1415" velocity="1"/>
		<origin rpy="0.981045015328298 1.7830455555994018 2.3426836466267447" xyz="0.16505111131043437 0.3182110402838252 0.4248115381964995"/>
	</joint>
	<joint name="23_to_11" type="revolute">
		<parent link="11"/>
		<child link="23"/>
		<axis xyz="0 1 0"/>
		<limit effort="1" upper="-3.1415" lower="3.1415" velocity="1"/>
		<origin rpy="1.471567522992447 1.7830455555994018 2.3426836466267447" xyz="0.16505111131043437 0.3182110402838252 0.4248115381964995"/>
	</joint>
	<joint name="24_to_11" type="revolute">
		<parent link="11"/>
		<child link="24"/>
		<axis xyz="0 1 0"/>
		<limit effort="1" upper="-3.1415" lower="3.1415" velocity="1"/>
		<origin rpy="1.962090030656596 1.7830455555994018 2.3426836466267447" xyz="0.16505111131043437 0.3182110402838252 0.4248115381964995"/>
	</joint>
	<joint name="25_to_11" type="revolute">
		<parent link="11"/>
		<child link="25"/>
		<axis xyz="0 1 0"/>
		<limit effort="1" upper="-3.1415" lower="3.1415" velocity="1"/>
		<origin rpy="2.452612538320745 1.7830455555994018 2.3426836466267447" xyz="0.16505111131043437 0.3182110402838252 0.4248115381964995"/>
	</joint>
	<joint name="36_to_11" type="revolute">
		<parent link="11"/>
		<child link="36"/>
		<axis xyz="0 1 0"/>
		<limit effort="1" upper="-3.1415" lower="3.1415" velocity="1"/>
		<origin rpy="35.62721993248391 1.1772698395437622 4.298590261165607" xyz="0.011445276436508722 0.39347760896457884 0.1621124317178898"/>
	</joint>
	<joint name="37_to_11" type="revolute">
		<parent link="11"/>
		<child link="37"/>
		<axis xyz="0 1 0"/>
		<limit effort="1" upper="-3.1415" lower="3.1415" velocity="1"/>
		<origin rpy="41.56508992123123 1.1772698395437622 4.298590261165607" xyz="0.011445276436508722 0.39347760896457884 0.1621124317178898"/>
	</joint>
	<joint name="38_to_11" type="revolute">
		<parent link="11"/>
		<child link="38"/>
		<axis xyz="0 1 0"/>
		<limit effort="1" upper="-3.1415" lower="3.1415" velocity="1"/>
		<origin rpy="47.50295990997854 1.1772698395437622 4.298590261165607" xyz="0.011445276436508722 0.39347760896457884 0.1621124317178898"/>
	</joint>
</robot>
