<robot name="jiejie">
	<link name="0">
		<visual>
			<geometry>
				<cylinder length="0.5641479681169879" radius="0.26727827258799963"/>
			</geometry>
		</visual>
		<collision>
			<geometry>
				<cylinder length="0.5641479681169879" radius="0.26727827258799963"/>
			</geometry>
		</collision>
		<inertial>
			<mass value="0.1266106424782611"/>
			<inertia ixx="0.03" iyy="0.03" izz="0.03" ixy="0" ixz="0" iyx="0"/>
		</inertial>
	</link>
	<link name="11">
		<visual>
			<geometry>
				<cylinder length="0.3991762151685897" radius="0.9286047724461834"/>
			</geometry>
		</visual>
		<collision>
			<geometry>
				<cylinder length="0.3991762151685897" radius="0.9286047724461834"/>
			</geometry>
		</collision>
		<inertial>
			<mass value="1.0813750656931778"/>
			<inertia ixx="0.03" iyy="0.03" izz="0.03" ixy="0" ixz="0" iyx="0"/>
		</inertial>
	</link>
	<link name="22">
		<visual>
			<geometry>
				<cylinder length="0.9913247191047079" radius="0.23499543261728517"/>
			</geometry>
		</visual>
		<collision>
			<geometry>
				<cylinder length="0.9913247191047079" radius="0.23499543261728517"/>
			</geometry>
		</collision>
		<inertial>
			<mass value="0.1719826557781397"/>
			<inertia ixx="0.03" iyy="0.03" izz="0.03" ixy="0" ixz="0" iyx="0"/>
		</inertial>
	</link>
	<joint name="11_to_0" type="revolute">
		<parent link="0"/>
		<child link="11"/>
		<axis xyz="0 0 1"/>
		<limit effort="1" upper="-3.1415" lower="3.1415" velocity="1"/>
		<origin rpy="0.17934487013463388 5.346351575067694 4.607088505421354" xyz="0.47937751848951704 0.17493281279465944 0.12482231719935388"/>
	</joint>
	<joint name="22_to_0" type="revolute">
		<parent link="0"/>
		<child link="22"/>
		<axis xyz="1 0 0"/>
		<limit effort="1" upper="-3.1415" lower="3.1415" velocity="1"/>
		<origin rpy="10.082666290617706 1.308169514647243 3.285481549493712" xyz="0.05201508349126427 0.8442719017248157 0.520904250296006"/>
	</joint>
</robot>
