<robot name="jiejie">
	<link name="0">
		<visual>
			<geometry>
				<cylinder length="0.7373221410868707" radius="0.9999"/>
			</geometry>
		</visual>
		<collision>
			<geometry>
				<cylinder length="0.7373221410868707" radius="0.9999"/>
			</geometry>
		</collision>
		<inertial>
			<mass value="2.3159025717669146"/>
			<inertia ixx="0.03" iyy="0.03" izz="0.03" ixy="0" ixz="0" iyx="0"/>
		</inertial>
	</link>
	<link name="11">
		<visual>
			<geometry>
				<cylinder length="0.6621201894926178" radius="0.246265328934829"/>
			</geometry>
		</visual>
		<collision>
			<geometry>
				<cylinder length="0.6621201894926178" radius="0.246265328934829"/>
			</geometry>
		</collision>
		<inertial>
			<mass value="0.12615174120664693"/>
			<inertia ixx="0.03" iyy="0.03" izz="0.03" ixy="0" ixz="0" iyx="0"/>
		</inertial>
	</link>
	<link name="22">
		<visual>
			<geometry>
				<cylinder length="0.7373221410868707" radius="0.9999"/>
			</geometry>
		</visual>
		<collision>
			<geometry>
				<cylinder length="0.7373221410868707" radius="0.9999"/>
			</geometry>
		</collision>
		<inertial>
			<mass value="2.3159025717669146"/>
			<inertia ixx="0.03" iyy="0.03" izz="0.03" ixy="0" ixz="0" iyx="0"/>
		</inertial>
	</link>
	<link name="23">
		<visual>
			<geometry>
				<cylinder length="0.7373221410868707" radius="0.9999"/>
			</geometry>
		</visual>
		<collision>
			<geometry>
				<cylinder length="0.7373221410868707" radius="0.9999"/>
			</geometry>
		</collision>
		<inertial>
			<mass value="2.3159025717669146"/>
			<inertia ixx="0.03" iyy="0.03" izz="0.03" ixy="0" ixz="0" iyx="0"/>
		</inertial>
	</link>
	<link name="24">
		<visual>
			<geometry>
				<cylinder length="0.7373221410868707" radius="0.9999"/>
			</geometry>
		</visual>
		<collision>
			<geometry>
				<cylinder length="0.7373221410868707" radius="0.9999"/>
			</geometry>
		</collision>
		<inertial>
			<mass value="2.3159025717669146"/>
			<inertia ixx="0.03" iyy="0.03" izz="0.03" ixy="0" ixz="0" iyx="0"/>
		</inertial>
	</link>
	<link name="25">
		<visual>
			<geometry>
				<cylinder length="0.7373221410868707" radius="0.9999"/>
			</geometry>
		</visual>
		<collision>
			<geometry>
				<cylinder length="0.7373221410868707" radius="0.9999"/>
			</geometry>
		</collision>
		<inertial>
			<mass value="2.3159025717669146"/>
			<inertia ixx="0.03" iyy="0.03" izz="0.03" ixy="0" ixz="0" iyx="0"/>
		</inertial>
	</link>
	<link name="16">
		<visual>
			<geometry>
				<cylinder length="0.6621201894926178" radius="0.246265328934829"/>
			</geometry>
		</visual>
		<collision>
			<geometry>
				<cylinder length="0.6621201894926178" radius="0.246265328934829"/>
			</geometry>
		</collision>
		<inertial>
			<mass value="0.12615174120664693"/>
			<inertia ixx="0.03" iyy="0.03" izz="0.03" ixy="0" ixz="0" iyx="0"/>
		</inertial>
	</link>
	<link name="27">
		<visual>
			<geometry>
				<cylinder length="0.7373221410868707" radius="0.9999"/>
			</geometry>
		</visual>
		<collision>
			<geometry>
				<cylinder length="0.7373221410868707" radius="0.9999"/>
			</geometry>
		</collision>
		<inertial>
			<mass value="2.3159025717669146"/>
			<inertia ixx="0.03" iyy="0.03" izz="0.03" ixy="0" ixz="0" iyx="0"/>
		</inertial>
	</link>
	<link name="28">
		<visual>
			<geometry>
				<cylinder length="0.7373221410868707" radius="0.9999"/>
			</geometry>
		</visual>
		<collision>
			<geometry>
				<cylinder length="0.7373221410868707" radius="0.9999"/>
			</geometry>
		</collision>
		<inertial>
			<mass value="2.3159025717669146"/>
			<inertia ixx="0.03" iyy="0.03" izz="0.03" ixy="0" ixz="0" iyx="0"/>
		</inertial>
	</link>
	<link name="29">
		<visual>
			<geometry>
				<cylinder length="0.7373221410868707" radius="0.9999"/>
			</geometry>
		</visual>
		<collision>
			<geometry>
				<cylinder length="0.7373221410868707" radius="0.9999"/>
			</geometry>
		</collision>
		<inertial>
			<mass value="2.3159025717669146"/>
			<inertia ixx="0.03" iyy="0.03" izz="0.03" ixy="0" ixz="0" iyx="0"/>
		</inertial>
	</link>
	<link name="210">
		<visual>
			<geometry>
				<cylinder length="0.7373221410868707" radius="0.9999"/>
			</geometry>
		</visual>
		<collision>
			<geometry>
				<cylinder length="0.7373221410868707" radius="0.9999"/>
			</geometry>
		</collision>
		<inertial>
			<mass value="2.3159025717669146"/>
			<inertia ixx="0.03" iyy="0.03" izz="0.03" ixy="0" ixz="0" iyx="0"/>
		</inertial>
	</link>
	<link name="111">
		<visual>
			<geometry>
				<cylinder length="0.6621201894926178" radius="0.246265328934829"/>
			</geometry>
		</visual>
		<collision>
			<geometry>
				<cylinder length="0.6621201894926178" radius="0.246265328934829"/>
			</geometry>
		</collision>
		<inertial>
			<mass value="0.12615174120664693"/>
			<inertia ixx="0.03" iyy="0.03" izz="0.03" ixy="0" ixz="0" iyx="0"/>
		</inertial>
	</link>
	<link name="212">
		<visual>
			<geometry>
				<cylinder length="0.7373221410868707" radius="0.9999"/>
			</geometry>
		</visual>
		<collision>
			<geometry>
				<cylinder length="0.7373221410868707" radius="0.9999"/>
			</geometry>
		</collision>
		<inertial>
			<mass value="2.3159025717669146"/>
			<inertia ixx="0.03" iyy="0.03" izz="0.03" ixy="0" ixz="0" iyx="0"/>
		</inertial>
	</link>
	<link name="213">
		<visual>
			<geometry>
				<cylinder length="0.7373221410868707" radius="0.9999"/>
			</geometry>
		</visual>
		<collision>
			<geometry>
				<cylinder length="0.7373221410868707" radius="0.9999"/>
			</geometry>
		</collision>
		<inertial>
			<mass value="2.3159025717669146"/>
			<inertia ixx="0.03" iyy="0.03" izz="0.03" ixy="0" ixz="0" iyx="0"/>
		</inertial>
	</link>
	<link name="214">
		<visual>
			<geometry>
				<cylinder length="0.7373221410868707" radius="0.9999"/>
			</geometry>
		</visual>
		<collision>
			<geometry>
				<cylinder length="0.7373221410868707" radius="0.9999"/>
			</geometry>
		</collision>
		<inertial>
			<mass value="2.3159025717669146"/>
			<inertia ixx="0.03" iyy="0.03" izz="0.03" ixy="0" ixz="0" iyx="0"/>
		</inertial>
	</link>
	<link name="215">
		<visual>
			<geometry>
				<cylinder length="0.7373221410868707" radius="0.9999"/>
			</geometry>
		</visual>
		<collision>
			<geometry>
				<cylinder length="0.7373221410868707" radius="0.9999"/>
			</geometry>
		</collision>
		<inertial>
			<mass value="2.3159025717669146"/>
			<inertia ixx="0.03" iyy="0.03" izz="0.03" ixy="0" ixz="0" iyx="0"/>
		</inertial>
	</link>
	<joint name="11_to_0" type="revolute">
		<parent link="0"/>
		<child link="11"/>
		<axis xyz="1 0 0"/>
		<limit effort="1" upper="-3.1415" lower="3.1415" velocity="1"/>
		<origin rpy="12.463017501597609 3.826992907153868 4.104114553209477" xyz="0.8429589359258589 0.7886703401700738 0.9999"/>
	</joint>
	<joint name="22_to_11" type="revolute">
		<parent link="11"/>
		<child link="22"/>
		<axis xyz="0 0 1"/>
		<limit effort="1" upper="-3.1415" lower="3.1415" velocity="1"/>
		<origin rpy="11.079669023719557 0.7499782918577459 2.3383200886764004" xyz="0.322992367260043 0.5415013497695964 0.7138715724943219"/>
	</joint>
	<joint name="23_to_11" type="revolute">
		<parent link="11"/>
		<child link="23"/>
		<axis xyz="0 0 1"/>
		<limit effort="1" upper="-3.1415" lower="3.1415" velocity="1"/>
		<origin rpy="16.619503535579334 0.7499782918577459 2.3383200886764004" xyz="0.322992367260043 0.5415013497695964 0.7138715724943219"/>
	</joint>
	<joint name="24_to_11" type="revolute">
		<parent link="11"/>
		<child link="24"/>
		<axis xyz="0 0 1"/>
		<limit effort="1" upper="-3.1415" lower="3.1415" velocity="1"/>
		<origin rpy="22.159338047439114 0.7499782918577459 2.3383200886764004" xyz="0.322992367260043 0.5415013497695964 0.7138715724943219"/>
	</joint>
	<joint name="25_to_11" type="revolute">
		<parent link="11"/>
		<child link="25"/>
		<axis xyz="0 0 1"/>
		<limit effort="1" upper="-3.1415" lower="3.1415" velocity="1"/>
		<origin rpy="27.699172559298894 0.7499782918577459 2.3383200886764004" xyz="0.322992367260043 0.5415013497695964 0.7138715724943219"/>
	</joint>
	<joint name="16_to_0" type="revolute">
		<parent link="0"/>
		<child link="16"/>
		<axis xyz="1 0 0"/>
		<limit effort="1" upper="-3.1415" lower="3.1415" velocity="1"/>
		<origin rpy="18.694526252396415 3.826992907153868 4.104114553209477" xyz="0.8429589359258589 0.7886703401700738 0.9999"/>
	</joint>
	<joint name="27_to_16" type="revolute">
		<parent link="16"/>
		<child link="27"/>
		<axis xyz="0 0 1"/>
		<limit effort="1" upper="-3.1415" lower="3.1415" velocity="1"/>
		<origin rpy="11.079669023719557 0.7499782918577459 2.3383200886764004" xyz="0.322992367260043 0.5415013497695964 0.7138715724943219"/>
	</joint>
	<joint name="28_to_16" type="revolute">
		<parent link="16"/>
		<child link="28"/>
		<axis xyz="0 0 1"/>
		<limit effort="1" upper="-3.1415" lower="3.1415" velocity="1"/>
		<origin rpy="16.619503535579334 0.7499782918577459 2.3383200886764004" xyz="0.322992367260043 0.5415013497695964 0.7138715724943219"/>
	</joint>
	<joint name="29_to_16" type="revolute">
		<parent link="16"/>
		<child link="29"/>
		<axis xyz="0 0 1"/>
		<limit effort="1" upper="-3.1415" lower="3.1415" velocity="1"/>
		<origin rpy="22.159338047439114 0.7499782918577459 2.3383200886764004" xyz="0.322992367260043 0.5415013497695964 0.7138715724943219"/>
	</joint>
	<joint name="210_to_16" type="revolute">
		<parent link="16"/>
		<child link="210"/>
		<axis xyz="0 0 1"/>
		<limit effort="1" upper="-3.1415" lower="3.1415" velocity="1"/>
		<origin rpy="27.699172559298894 0.7499782918577459 2.3383200886764004" xyz="0.322992367260043 0.5415013497695964 0.7138715724943219"/>
	</joint>
	<joint name="111_to_0" type="revolute">
		<parent link="0"/>
		<child link="111"/>
		<axis xyz="1 0 0"/>
		<limit effort="1" upper="-3.1415" lower="3.1415" velocity="1"/>
		<origin rpy="24.926035003195217 3.826992907153868 4.104114553209477" xyz="0.8429589359258589 0.7886703401700738 0.9999"/>
	</joint>
	<joint name="212_to_111" type="revolute">
		<parent link="111"/>
		<child link="212"/>
		<axis xyz="0 0 1"/>
		<limit effort="1" upper="-3.1415" lower="3.1415" velocity="1"/>
		<origin rpy="11.079669023719557 0.7499782918577459 2.3383200886764004" xyz="0.322992367260043 0.5415013497695964 0.7138715724943219"/>
	</joint>
	<joint name="213_to_111" type="revolute">
		<parent link="111"/>
		<child link="213"/>
		<axis xyz="0 0 1"/>
		<limit effort="1" upper="-3.1415" lower="3.1415" velocity="1"/>
		<origin rpy="16.619503535579334 0.7499782918577459 2.3383200886764004" xyz="0.322992367260043 0.5415013497695964 0.7138715724943219"/>
	</joint>
	<joint name="214_to_111" type="revolute">
		<parent link="111"/>
		<child link="214"/>
		<axis xyz="0 0 1"/>
		<limit effort="1" upper="-3.1415" lower="3.1415" velocity="1"/>
		<origin rpy="22.159338047439114 0.7499782918577459 2.3383200886764004" xyz="0.322992367260043 0.5415013497695964 0.7138715724943219"/>
	</joint>
	<joint name="215_to_111" type="revolute">
		<parent link="111"/>
		<child link="215"/>
		<axis xyz="0 0 1"/>
		<limit effort="1" upper="-3.1415" lower="3.1415" velocity="1"/>
		<origin rpy="27.699172559298894 0.7499782918577459 2.3383200886764004" xyz="0.322992367260043 0.5415013497695964 0.7138715724943219"/>
	</joint>
</robot>
